[2023-01-06T13:20:21.956+0000] {taskinstance.py:1171} INFO - Dependencies all met for <TaskInstance: atn_import_data_from_apis.check_api_data_quality_ctrl_step scheduled__2023-01-06T00:00:00+00:00 [queued]>
[2023-01-06T13:20:21.971+0000] {taskinstance.py:1171} INFO - Dependencies all met for <TaskInstance: atn_import_data_from_apis.check_api_data_quality_ctrl_step scheduled__2023-01-06T00:00:00+00:00 [queued]>
[2023-01-06T13:20:21.971+0000] {taskinstance.py:1368} INFO - 
--------------------------------------------------------------------------------
[2023-01-06T13:20:21.971+0000] {taskinstance.py:1369} INFO - Starting attempt 2 of 3
[2023-01-06T13:20:21.971+0000] {taskinstance.py:1370} INFO - 
--------------------------------------------------------------------------------
[2023-01-06T13:20:21.984+0000] {taskinstance.py:1389} INFO - Executing <Task(EmrStepSensor): check_api_data_quality_ctrl_step> on 2023-01-06 00:00:00+00:00
[2023-01-06T13:20:21.988+0000] {standard_task_runner.py:52} INFO - Started process 284 to run task
[2023-01-06T13:20:21.991+0000] {standard_task_runner.py:79} INFO - Running: ['***', 'tasks', 'run', 'atn_import_data_from_apis', 'check_api_data_quality_ctrl_step', 'scheduled__2023-01-06T00:00:00+00:00', '--job-id', '3892', '--raw', '--subdir', 'DAGS_FOLDER/market_data_analytics/my_dags/import_data_from_apis.py', '--cfg-path', '/tmp/tmp6x32c111', '--error-file', '/tmp/tmp5w_zf23s']
[2023-01-06T13:20:21.992+0000] {standard_task_runner.py:80} INFO - Job 3892: Subtask check_api_data_quality_ctrl_step
[2023-01-06T13:20:22.006+0000] {warnings.py:110} WARNING - /home/***/.local/lib/python3.7/site-packages/***/configuration.py:538: DeprecationWarning: The sql_alchemy_conn option in [core] has been moved to the sql_alchemy_conn option in [database] - the old setting has been used, but please update your config.
  option = self._get_environment_variables(deprecated_key, deprecated_section, key, section)

[2023-01-06T13:20:22.056+0000] {task_command.py:371} INFO - Running <TaskInstance: atn_import_data_from_apis.check_api_data_quality_ctrl_step scheduled__2023-01-06T00:00:00+00:00 [running]> on host 370ed6868bc3
[2023-01-06T13:20:22.144+0000] {taskinstance.py:1583} INFO - Exporting the following env vars:
AIRFLOW_CTX_DAG_OWNER=atn
AIRFLOW_CTX_DAG_ID=atn_import_data_from_apis
AIRFLOW_CTX_TASK_ID=check_api_data_quality_ctrl_step
AIRFLOW_CTX_EXECUTION_DATE=2023-01-06T00:00:00+00:00
AIRFLOW_CTX_TRY_NUMBER=2
AIRFLOW_CTX_DAG_RUN_ID=scheduled__2023-01-06T00:00:00+00:00
[2023-01-06T13:20:22.154+0000] {base.py:68} INFO - Using connection ID 'aws_credentials' for task execution.
[2023-01-06T13:20:22.154+0000] {connection_wrapper.py:210} INFO - AWS Connection (conn_id='aws_credentials', conn_type='aws') credentials retrieved from login and password.
[2023-01-06T13:20:22.195+0000] {emr.py:443} INFO - Poking step s-1ZLNM0H7R0A4I on cluster j-3J07UP5RPSGPC
[2023-01-06T13:20:23.304+0000] {emr.py:69} INFO - Job flow currently FAILED
[2023-01-06T13:20:23.391+0000] {taskinstance.py:1902} ERROR - Task failed with exception
Traceback (most recent call last):
  File "/home/airflow/.local/lib/python3.7/site-packages/airflow/sensors/base.py", line 277, in execute
    poke_return = self.poke(context)
  File "/home/airflow/.local/lib/python3.7/site-packages/airflow/providers/amazon/aws/sensors/emr.py", line 79, in poke
    raise AirflowException(final_message)
airflow.exceptions.AirflowException: EMR job failed for reason Unknown Error. with message None and log file s3://atn-dl-data/logs/j-3J07UP5RPSGPC/steps/s-1ZLNM0H7R0A4I/
[2023-01-06T13:20:23.396+0000] {taskinstance.py:1412} INFO - Marking task as UP_FOR_RETRY. dag_id=atn_import_data_from_apis, task_id=check_api_data_quality_ctrl_step, execution_date=20230106T000000, start_date=20230106T132021, end_date=20230106T132023
[2023-01-06T13:20:23.409+0000] {standard_task_runner.py:97} ERROR - Failed to execute job 3892 for task check_api_data_quality_ctrl_step (EMR job failed for reason Unknown Error. with message None and log file s3://atn-dl-data/logs/j-3J07UP5RPSGPC/steps/s-1ZLNM0H7R0A4I/; 284)
[2023-01-06T13:20:23.417+0000] {local_task_job.py:156} INFO - Task exited with return code 1
[2023-01-06T13:20:23.456+0000] {local_task_job.py:279} INFO - 0 downstream tasks scheduled from follow-on schedule check
