[2023-01-06T13:12:44.350+0000] {taskinstance.py:1171} INFO - Dependencies all met for <TaskInstance: atn_import_data_from_apis.check_get_tickers_tweets_step scheduled__2023-01-06T00:00:00+00:00 [queued]>
[2023-01-06T13:12:44.364+0000] {taskinstance.py:1171} INFO - Dependencies all met for <TaskInstance: atn_import_data_from_apis.check_get_tickers_tweets_step scheduled__2023-01-06T00:00:00+00:00 [queued]>
[2023-01-06T13:12:44.364+0000] {taskinstance.py:1368} INFO - 
--------------------------------------------------------------------------------
[2023-01-06T13:12:44.364+0000] {taskinstance.py:1369} INFO - Starting attempt 1 of 3
[2023-01-06T13:12:44.365+0000] {taskinstance.py:1370} INFO - 
--------------------------------------------------------------------------------
[2023-01-06T13:12:44.377+0000] {taskinstance.py:1389} INFO - Executing <Task(EmrStepSensor): check_get_tickers_tweets_step> on 2023-01-06 00:00:00+00:00
[2023-01-06T13:12:44.382+0000] {standard_task_runner.py:52} INFO - Started process 276 to run task
[2023-01-06T13:12:44.385+0000] {standard_task_runner.py:79} INFO - Running: ['***', 'tasks', 'run', 'atn_import_data_from_apis', 'check_get_tickers_tweets_step', 'scheduled__2023-01-06T00:00:00+00:00', '--job-id', '3888', '--raw', '--subdir', 'DAGS_FOLDER/market_data_analytics/my_dags/import_data_from_apis.py', '--cfg-path', '/tmp/tmp_p_2gani', '--error-file', '/tmp/tmpomi_h19z']
[2023-01-06T13:12:44.385+0000] {standard_task_runner.py:80} INFO - Job 3888: Subtask check_get_tickers_tweets_step
[2023-01-06T13:12:44.399+0000] {warnings.py:110} WARNING - /home/***/.local/lib/python3.7/site-packages/***/configuration.py:538: DeprecationWarning: The sql_alchemy_conn option in [core] has been moved to the sql_alchemy_conn option in [database] - the old setting has been used, but please update your config.
  option = self._get_environment_variables(deprecated_key, deprecated_section, key, section)

[2023-01-06T13:12:44.451+0000] {task_command.py:371} INFO - Running <TaskInstance: atn_import_data_from_apis.check_get_tickers_tweets_step scheduled__2023-01-06T00:00:00+00:00 [running]> on host 370ed6868bc3
[2023-01-06T13:12:44.543+0000] {taskinstance.py:1583} INFO - Exporting the following env vars:
AIRFLOW_CTX_DAG_OWNER=atn
AIRFLOW_CTX_DAG_ID=atn_import_data_from_apis
AIRFLOW_CTX_TASK_ID=check_get_tickers_tweets_step
AIRFLOW_CTX_EXECUTION_DATE=2023-01-06T00:00:00+00:00
AIRFLOW_CTX_TRY_NUMBER=1
AIRFLOW_CTX_DAG_RUN_ID=scheduled__2023-01-06T00:00:00+00:00
[2023-01-06T13:12:44.553+0000] {base.py:68} INFO - Using connection ID 'aws_credentials' for task execution.
[2023-01-06T13:12:44.553+0000] {connection_wrapper.py:210} INFO - AWS Connection (conn_id='aws_credentials', conn_type='aws') credentials retrieved from login and password.
[2023-01-06T13:12:44.592+0000] {emr.py:443} INFO - Poking step s-2BVMC3E8WL6BS on cluster j-3J07UP5RPSGPC
[2023-01-06T13:12:45.711+0000] {emr.py:69} INFO - Job flow currently PENDING
[2023-01-06T13:13:45.746+0000] {emr.py:443} INFO - Poking step s-2BVMC3E8WL6BS on cluster j-3J07UP5RPSGPC
[2023-01-06T13:13:57.363+0000] {emr.py:69} INFO - Job flow currently RUNNING
[2023-01-06T13:14:57.423+0000] {emr.py:443} INFO - Poking step s-2BVMC3E8WL6BS on cluster j-3J07UP5RPSGPC
[2023-01-06T13:15:57.836+0000] {taskinstance.py:1902} ERROR - Task failed with exception
Traceback (most recent call last):
  File "/home/airflow/.local/lib/python3.7/site-packages/urllib3/connection.py", line 175, in _new_conn
    (self._dns_host, self.port), self.timeout, **extra_kw
  File "/home/airflow/.local/lib/python3.7/site-packages/urllib3/util/connection.py", line 72, in create_connection
    for res in socket.getaddrinfo(host, port, family, socket.SOCK_STREAM):
  File "/usr/local/lib/python3.7/socket.py", line 752, in getaddrinfo
    for res in _socket.getaddrinfo(host, port, family, type, proto, flags):
socket.gaierror: [Errno -3] Temporary failure in name resolution

During handling of the above exception, another exception occurred:

Traceback (most recent call last):
  File "/home/airflow/.local/lib/python3.7/site-packages/botocore/httpsession.py", line 457, in send
    chunked=self._chunked(request.headers),
  File "/home/airflow/.local/lib/python3.7/site-packages/urllib3/connectionpool.py", line 788, in urlopen
    method, url, error=e, _pool=self, _stacktrace=sys.exc_info()[2]
  File "/home/airflow/.local/lib/python3.7/site-packages/urllib3/util/retry.py", line 525, in increment
    raise six.reraise(type(error), error, _stacktrace)
  File "/home/airflow/.local/lib/python3.7/site-packages/urllib3/packages/six.py", line 770, in reraise
    raise value
  File "/home/airflow/.local/lib/python3.7/site-packages/urllib3/connectionpool.py", line 710, in urlopen
    chunked=chunked,
  File "/home/airflow/.local/lib/python3.7/site-packages/urllib3/connectionpool.py", line 386, in _make_request
    self._validate_conn(conn)
  File "/home/airflow/.local/lib/python3.7/site-packages/urllib3/connectionpool.py", line 1042, in _validate_conn
    conn.connect()
  File "/home/airflow/.local/lib/python3.7/site-packages/urllib3/connection.py", line 358, in connect
    self.sock = conn = self._new_conn()
  File "/home/airflow/.local/lib/python3.7/site-packages/urllib3/connection.py", line 187, in _new_conn
    self, "Failed to establish a new connection: %s" % e
urllib3.exceptions.NewConnectionError: <botocore.awsrequest.AWSHTTPSConnection object at 0x7fc1109c0510>: Failed to establish a new connection: [Errno -3] Temporary failure in name resolution

During handling of the above exception, another exception occurred:

Traceback (most recent call last):
  File "/home/airflow/.local/lib/python3.7/site-packages/airflow/sensors/base.py", line 277, in execute
    poke_return = self.poke(context)
  File "/home/airflow/.local/lib/python3.7/site-packages/airflow/providers/amazon/aws/sensors/emr.py", line 62, in poke
    response = self.get_emr_response()
  File "/home/airflow/.local/lib/python3.7/site-packages/airflow/providers/amazon/aws/sensors/emr.py", line 444, in get_emr_response
    return emr_client.describe_step(ClusterId=self.job_flow_id, StepId=self.step_id)
  File "/home/airflow/.local/lib/python3.7/site-packages/botocore/client.py", line 508, in _api_call
    return self._make_api_call(operation_name, kwargs)
  File "/home/airflow/.local/lib/python3.7/site-packages/botocore/client.py", line 899, in _make_api_call
    operation_model, request_dict, request_context
  File "/home/airflow/.local/lib/python3.7/site-packages/botocore/client.py", line 921, in _make_request
    return self._endpoint.make_request(operation_model, request_dict)
  File "/home/airflow/.local/lib/python3.7/site-packages/botocore/endpoint.py", line 119, in make_request
    return self._send_request(request_dict, operation_model)
  File "/home/airflow/.local/lib/python3.7/site-packages/botocore/endpoint.py", line 207, in _send_request
    exception,
  File "/home/airflow/.local/lib/python3.7/site-packages/botocore/endpoint.py", line 361, in _needs_retry
    request_dict=request_dict,
  File "/home/airflow/.local/lib/python3.7/site-packages/botocore/hooks.py", line 412, in emit
    return self._emitter.emit(aliased_event_name, **kwargs)
  File "/home/airflow/.local/lib/python3.7/site-packages/botocore/hooks.py", line 256, in emit
    return self._emit(event_name, kwargs)
  File "/home/airflow/.local/lib/python3.7/site-packages/botocore/hooks.py", line 239, in _emit
    response = handler(**kwargs)
  File "/home/airflow/.local/lib/python3.7/site-packages/botocore/retryhandler.py", line 207, in __call__
    if self._checker(**checker_kwargs):
  File "/home/airflow/.local/lib/python3.7/site-packages/botocore/retryhandler.py", line 285, in __call__
    attempt_number, response, caught_exception
  File "/home/airflow/.local/lib/python3.7/site-packages/botocore/retryhandler.py", line 320, in _should_retry
    return self._checker(attempt_number, response, caught_exception)
  File "/home/airflow/.local/lib/python3.7/site-packages/botocore/retryhandler.py", line 364, in __call__
    attempt_number, response, caught_exception
  File "/home/airflow/.local/lib/python3.7/site-packages/botocore/retryhandler.py", line 248, in __call__
    attempt_number, caught_exception
  File "/home/airflow/.local/lib/python3.7/site-packages/botocore/retryhandler.py", line 416, in _check_caught_exception
    raise caught_exception
  File "/home/airflow/.local/lib/python3.7/site-packages/botocore/endpoint.py", line 281, in _do_get_response
    http_response = self._send(request)
  File "/home/airflow/.local/lib/python3.7/site-packages/botocore/endpoint.py", line 377, in _send
    return self.http_session.send(request)
  File "/home/airflow/.local/lib/python3.7/site-packages/botocore/httpsession.py", line 477, in send
    raise EndpointConnectionError(endpoint_url=request.url, error=e)
botocore.exceptions.EndpointConnectionError: Could not connect to the endpoint URL: "https://us-west-2.elasticmapreduce.amazonaws.com/"
[2023-01-06T13:15:57.900+0000] {taskinstance.py:1412} INFO - Marking task as UP_FOR_RETRY. dag_id=atn_import_data_from_apis, task_id=check_get_tickers_tweets_step, execution_date=20230106T000000, start_date=20230106T131244, end_date=20230106T131557
[2023-01-06T13:15:57.922+0000] {standard_task_runner.py:97} ERROR - Failed to execute job 3888 for task check_get_tickers_tweets_step (Could not connect to the endpoint URL: "https://us-west-2.elasticmapreduce.amazonaws.com/"; 276)
[2023-01-06T13:15:57.932+0000] {local_task_job.py:156} INFO - Task exited with return code 1
[2023-01-06T13:15:57.970+0000] {local_task_job.py:279} INFO - 0 downstream tasks scheduled from follow-on schedule check
