[2023-01-08T15:01:56.671+0000] {taskinstance.py:1171} INFO - Dependencies all met for <TaskInstance: atn_import_data_from_apis.check_api_data_quality_ctrl_step manual__2023-01-08T14:20:41.774645+00:00 [queued]>
[2023-01-08T15:01:56.686+0000] {taskinstance.py:1171} INFO - Dependencies all met for <TaskInstance: atn_import_data_from_apis.check_api_data_quality_ctrl_step manual__2023-01-08T14:20:41.774645+00:00 [queued]>
[2023-01-08T15:01:56.687+0000] {taskinstance.py:1368} INFO - 
--------------------------------------------------------------------------------
[2023-01-08T15:01:56.687+0000] {taskinstance.py:1369} INFO - Starting attempt 1 of 3
[2023-01-08T15:01:56.687+0000] {taskinstance.py:1370} INFO - 
--------------------------------------------------------------------------------
[2023-01-08T15:01:56.703+0000] {taskinstance.py:1389} INFO - Executing <Task(EmrStepSensor): check_api_data_quality_ctrl_step> on 2023-01-08 14:20:41.774645+00:00
[2023-01-08T15:01:56.708+0000] {standard_task_runner.py:52} INFO - Started process 236 to run task
[2023-01-08T15:01:56.711+0000] {standard_task_runner.py:79} INFO - Running: ['***', 'tasks', 'run', 'atn_import_data_from_apis', 'check_api_data_quality_ctrl_step', 'manual__2023-01-08T14:20:41.774645+00:00', '--job-id', '4027', '--raw', '--subdir', 'DAGS_FOLDER/market_data_analytics/my_dags/import_data_from_apis.py', '--cfg-path', '/tmp/tmp42d0yl9l', '--error-file', '/tmp/tmpkit1r8wk']
[2023-01-08T15:01:56.711+0000] {standard_task_runner.py:80} INFO - Job 4027: Subtask check_api_data_quality_ctrl_step
[2023-01-08T15:01:56.781+0000] {task_command.py:371} INFO - Running <TaskInstance: atn_import_data_from_apis.check_api_data_quality_ctrl_step manual__2023-01-08T14:20:41.774645+00:00 [running]> on host 370ed6868bc3
[2023-01-08T15:01:56.883+0000] {taskinstance.py:1583} INFO - Exporting the following env vars:
AIRFLOW_CTX_DAG_OWNER=atn
AIRFLOW_CTX_DAG_ID=atn_import_data_from_apis
AIRFLOW_CTX_TASK_ID=check_api_data_quality_ctrl_step
AIRFLOW_CTX_EXECUTION_DATE=2023-01-08T14:20:41.774645+00:00
AIRFLOW_CTX_TRY_NUMBER=1
AIRFLOW_CTX_DAG_RUN_ID=manual__2023-01-08T14:20:41.774645+00:00
[2023-01-08T15:01:56.895+0000] {base.py:68} INFO - Using connection ID 'aws_credentials' for task execution.
[2023-01-08T15:01:56.896+0000] {connection_wrapper.py:210} INFO - AWS Connection (conn_id='aws_credentials', conn_type='aws') credentials retrieved from login and password.
[2023-01-08T15:01:56.935+0000] {emr.py:443} INFO - Poking step s-3GQ8XRZSNHZ33 on cluster j-9LEVRHTCP62
[2023-01-08T15:01:57.656+0000] {emr.py:69} INFO - Job flow currently PENDING
[2023-01-08T15:02:57.693+0000] {emr.py:443} INFO - Poking step s-3GQ8XRZSNHZ33 on cluster j-9LEVRHTCP62
[2023-01-08T15:02:58.478+0000] {emr.py:69} INFO - Job flow currently RUNNING
[2023-01-08T15:03:58.516+0000] {emr.py:443} INFO - Poking step s-3GQ8XRZSNHZ33 on cluster j-9LEVRHTCP62
[2023-01-08T15:03:59.340+0000] {emr.py:69} INFO - Job flow currently FAILED
[2023-01-08T15:03:59.363+0000] {taskinstance.py:1902} ERROR - Task failed with exception
Traceback (most recent call last):
  File "/home/airflow/.local/lib/python3.7/site-packages/airflow/sensors/base.py", line 277, in execute
    poke_return = self.poke(context)
  File "/home/airflow/.local/lib/python3.7/site-packages/airflow/providers/amazon/aws/sensors/emr.py", line 79, in poke
    raise AirflowException(final_message)
airflow.exceptions.AirflowException: EMR job failed for reason Unknown Error. with message None and log file s3://atn-dl-data/logs/j-9LEVRHTCP62/steps/s-3GQ8XRZSNHZ33/
[2023-01-08T15:03:59.373+0000] {taskinstance.py:1412} INFO - Marking task as UP_FOR_RETRY. dag_id=atn_import_data_from_apis, task_id=check_api_data_quality_ctrl_step, execution_date=20230108T142041, start_date=20230108T150156, end_date=20230108T150359
[2023-01-08T15:03:59.398+0000] {standard_task_runner.py:97} ERROR - Failed to execute job 4027 for task check_api_data_quality_ctrl_step (EMR job failed for reason Unknown Error. with message None and log file s3://atn-dl-data/logs/j-9LEVRHTCP62/steps/s-3GQ8XRZSNHZ33/; 236)
[2023-01-08T15:03:59.432+0000] {local_task_job.py:156} INFO - Task exited with return code 1
[2023-01-08T15:03:59.621+0000] {local_task_job.py:279} INFO - 0 downstream tasks scheduled from follow-on schedule check
