[2023-01-08T15:06:03.523+0000] {taskinstance.py:1171} INFO - Dependencies all met for <TaskInstance: atn_import_data_from_apis.check_api_data_quality_ctrl_step manual__2023-01-08T14:20:41.774645+00:00 [queued]>
[2023-01-08T15:06:03.538+0000] {taskinstance.py:1171} INFO - Dependencies all met for <TaskInstance: atn_import_data_from_apis.check_api_data_quality_ctrl_step manual__2023-01-08T14:20:41.774645+00:00 [queued]>
[2023-01-08T15:06:03.538+0000] {taskinstance.py:1368} INFO - 
--------------------------------------------------------------------------------
[2023-01-08T15:06:03.539+0000] {taskinstance.py:1369} INFO - Starting attempt 3 of 3
[2023-01-08T15:06:03.539+0000] {taskinstance.py:1370} INFO - 
--------------------------------------------------------------------------------
[2023-01-08T15:06:03.552+0000] {taskinstance.py:1389} INFO - Executing <Task(EmrStepSensor): check_api_data_quality_ctrl_step> on 2023-01-08 14:20:41.774645+00:00
[2023-01-08T15:06:03.556+0000] {standard_task_runner.py:52} INFO - Started process 240 to run task
[2023-01-08T15:06:03.559+0000] {standard_task_runner.py:79} INFO - Running: ['***', 'tasks', 'run', 'atn_import_data_from_apis', 'check_api_data_quality_ctrl_step', 'manual__2023-01-08T14:20:41.774645+00:00', '--job-id', '4029', '--raw', '--subdir', 'DAGS_FOLDER/market_data_analytics/my_dags/import_data_from_apis.py', '--cfg-path', '/tmp/tmpvvpc0tm9', '--error-file', '/tmp/tmph2_hnixu']
[2023-01-08T15:06:03.559+0000] {standard_task_runner.py:80} INFO - Job 4029: Subtask check_api_data_quality_ctrl_step
[2023-01-08T15:06:03.620+0000] {task_command.py:371} INFO - Running <TaskInstance: atn_import_data_from_apis.check_api_data_quality_ctrl_step manual__2023-01-08T14:20:41.774645+00:00 [running]> on host 370ed6868bc3
[2023-01-08T15:06:03.733+0000] {taskinstance.py:1583} INFO - Exporting the following env vars:
AIRFLOW_CTX_DAG_OWNER=atn
AIRFLOW_CTX_DAG_ID=atn_import_data_from_apis
AIRFLOW_CTX_TASK_ID=check_api_data_quality_ctrl_step
AIRFLOW_CTX_EXECUTION_DATE=2023-01-08T14:20:41.774645+00:00
AIRFLOW_CTX_TRY_NUMBER=3
AIRFLOW_CTX_DAG_RUN_ID=manual__2023-01-08T14:20:41.774645+00:00
[2023-01-08T15:06:03.746+0000] {base.py:68} INFO - Using connection ID 'aws_credentials' for task execution.
[2023-01-08T15:06:03.747+0000] {connection_wrapper.py:210} INFO - AWS Connection (conn_id='aws_credentials', conn_type='aws') credentials retrieved from login and password.
[2023-01-08T15:06:03.784+0000] {emr.py:443} INFO - Poking step s-3GQ8XRZSNHZ33 on cluster j-9LEVRHTCP62
[2023-01-08T15:06:04.640+0000] {emr.py:69} INFO - Job flow currently FAILED
[2023-01-08T15:06:04.656+0000] {taskinstance.py:1902} ERROR - Task failed with exception
Traceback (most recent call last):
  File "/home/airflow/.local/lib/python3.7/site-packages/airflow/sensors/base.py", line 277, in execute
    poke_return = self.poke(context)
  File "/home/airflow/.local/lib/python3.7/site-packages/airflow/providers/amazon/aws/sensors/emr.py", line 79, in poke
    raise AirflowException(final_message)
airflow.exceptions.AirflowException: EMR job failed for reason Unknown Error. with message None and log file s3://atn-dl-data/logs/j-9LEVRHTCP62/steps/s-3GQ8XRZSNHZ33/
[2023-01-08T15:06:04.660+0000] {taskinstance.py:1412} INFO - Marking task as FAILED. dag_id=atn_import_data_from_apis, task_id=check_api_data_quality_ctrl_step, execution_date=20230108T142041, start_date=20230108T150603, end_date=20230108T150604
[2023-01-08T15:06:04.675+0000] {standard_task_runner.py:97} ERROR - Failed to execute job 4029 for task check_api_data_quality_ctrl_step (EMR job failed for reason Unknown Error. with message None and log file s3://atn-dl-data/logs/j-9LEVRHTCP62/steps/s-3GQ8XRZSNHZ33/; 240)
[2023-01-08T15:06:04.699+0000] {local_task_job.py:156} INFO - Task exited with return code 1
[2023-01-08T15:06:04.760+0000] {local_task_job.py:279} INFO - 1 downstream tasks scheduled from follow-on schedule check
