[2023-01-06T14:42:24.171+0000] {taskinstance.py:1171} INFO - Dependencies all met for <TaskInstance: atn_update_datalake.check_datalake_quality_ctrl_step manual__2023-01-06T13:21:32.663212+00:00 [queued]>
[2023-01-06T14:42:24.188+0000] {taskinstance.py:1171} INFO - Dependencies all met for <TaskInstance: atn_update_datalake.check_datalake_quality_ctrl_step manual__2023-01-06T13:21:32.663212+00:00 [queued]>
[2023-01-06T14:42:24.188+0000] {taskinstance.py:1368} INFO - 
--------------------------------------------------------------------------------
[2023-01-06T14:42:24.188+0000] {taskinstance.py:1369} INFO - Starting attempt 2 of 3
[2023-01-06T14:42:24.188+0000] {taskinstance.py:1370} INFO - 
--------------------------------------------------------------------------------
[2023-01-06T14:42:24.203+0000] {taskinstance.py:1389} INFO - Executing <Task(EmrStepSensor): check_datalake_quality_ctrl_step> on 2023-01-06 13:21:32.663212+00:00
[2023-01-06T14:42:24.209+0000] {standard_task_runner.py:52} INFO - Started process 449 to run task
[2023-01-06T14:42:24.212+0000] {standard_task_runner.py:79} INFO - Running: ['***', 'tasks', 'run', 'atn_update_datalake', 'check_datalake_quality_ctrl_step', 'manual__2023-01-06T13:21:32.663212+00:00', '--job-id', '3954', '--raw', '--subdir', 'DAGS_FOLDER/market_data_analytics/my_dags/datalake_update.py', '--cfg-path', '/tmp/tmpnssteatl', '--error-file', '/tmp/tmp2cw1g_nn']
[2023-01-06T14:42:24.212+0000] {standard_task_runner.py:80} INFO - Job 3954: Subtask check_datalake_quality_ctrl_step
[2023-01-06T14:42:24.279+0000] {task_command.py:371} INFO - Running <TaskInstance: atn_update_datalake.check_datalake_quality_ctrl_step manual__2023-01-06T13:21:32.663212+00:00 [running]> on host 370ed6868bc3
[2023-01-06T14:42:24.374+0000] {taskinstance.py:1583} INFO - Exporting the following env vars:
AIRFLOW_CTX_DAG_OWNER=atn
AIRFLOW_CTX_DAG_ID=atn_update_datalake
AIRFLOW_CTX_TASK_ID=check_datalake_quality_ctrl_step
AIRFLOW_CTX_EXECUTION_DATE=2023-01-06T13:21:32.663212+00:00
AIRFLOW_CTX_TRY_NUMBER=2
AIRFLOW_CTX_DAG_RUN_ID=manual__2023-01-06T13:21:32.663212+00:00
[2023-01-06T14:42:24.385+0000] {base.py:68} INFO - Using connection ID 'aws_credentials' for task execution.
[2023-01-06T14:42:24.385+0000] {connection_wrapper.py:210} INFO - AWS Connection (conn_id='aws_credentials', conn_type='aws') credentials retrieved from login and password.
[2023-01-06T14:42:24.424+0000] {emr.py:443} INFO - Poking step s-3650RIB09QRV0 on cluster j-3G7PO8Y3OE3BT
[2023-01-06T14:42:25.474+0000] {emr.py:69} INFO - Job flow currently FAILED
[2023-01-06T14:42:25.493+0000] {taskinstance.py:1902} ERROR - Task failed with exception
Traceback (most recent call last):
  File "/home/airflow/.local/lib/python3.7/site-packages/airflow/sensors/base.py", line 277, in execute
    poke_return = self.poke(context)
  File "/home/airflow/.local/lib/python3.7/site-packages/airflow/providers/amazon/aws/sensors/emr.py", line 79, in poke
    raise AirflowException(final_message)
airflow.exceptions.AirflowException: EMR job failed for reason Unknown Error. with message None and log file s3://atn-dl-data/logs/j-3G7PO8Y3OE3BT/steps/s-3650RIB09QRV0/
[2023-01-06T14:42:25.498+0000] {taskinstance.py:1412} INFO - Marking task as UP_FOR_RETRY. dag_id=atn_update_datalake, task_id=check_datalake_quality_ctrl_step, execution_date=20230106T132132, start_date=20230106T144224, end_date=20230106T144225
[2023-01-06T14:42:25.513+0000] {standard_task_runner.py:97} ERROR - Failed to execute job 3954 for task check_datalake_quality_ctrl_step (EMR job failed for reason Unknown Error. with message None and log file s3://atn-dl-data/logs/j-3G7PO8Y3OE3BT/steps/s-3650RIB09QRV0/; 449)
[2023-01-06T14:42:25.556+0000] {local_task_job.py:156} INFO - Task exited with return code 1
[2023-01-06T14:42:25.608+0000] {local_task_job.py:279} INFO - 0 downstream tasks scheduled from follow-on schedule check
