[2023-01-06T14:38:17.767+0000] {taskinstance.py:1171} INFO - Dependencies all met for <TaskInstance: atn_update_datalake.check_datalake_quality_ctrl_step manual__2023-01-06T13:21:32.663212+00:00 [queued]>
[2023-01-06T14:38:17.781+0000] {taskinstance.py:1171} INFO - Dependencies all met for <TaskInstance: atn_update_datalake.check_datalake_quality_ctrl_step manual__2023-01-06T13:21:32.663212+00:00 [queued]>
[2023-01-06T14:38:17.782+0000] {taskinstance.py:1368} INFO - 
--------------------------------------------------------------------------------
[2023-01-06T14:38:17.782+0000] {taskinstance.py:1369} INFO - Starting attempt 1 of 3
[2023-01-06T14:38:17.782+0000] {taskinstance.py:1370} INFO - 
--------------------------------------------------------------------------------
[2023-01-06T14:38:17.797+0000] {taskinstance.py:1389} INFO - Executing <Task(EmrStepSensor): check_datalake_quality_ctrl_step> on 2023-01-06 13:21:32.663212+00:00
[2023-01-06T14:38:17.802+0000] {standard_task_runner.py:52} INFO - Started process 447 to run task
[2023-01-06T14:38:17.806+0000] {standard_task_runner.py:79} INFO - Running: ['***', 'tasks', 'run', 'atn_update_datalake', 'check_datalake_quality_ctrl_step', 'manual__2023-01-06T13:21:32.663212+00:00', '--job-id', '3953', '--raw', '--subdir', 'DAGS_FOLDER/market_data_analytics/my_dags/datalake_update.py', '--cfg-path', '/tmp/tmpsx3jq9iv', '--error-file', '/tmp/tmpkjep3m1h']
[2023-01-06T14:38:17.806+0000] {standard_task_runner.py:80} INFO - Job 3953: Subtask check_datalake_quality_ctrl_step
[2023-01-06T14:38:17.866+0000] {task_command.py:371} INFO - Running <TaskInstance: atn_update_datalake.check_datalake_quality_ctrl_step manual__2023-01-06T13:21:32.663212+00:00 [running]> on host 370ed6868bc3
[2023-01-06T14:38:17.958+0000] {taskinstance.py:1583} INFO - Exporting the following env vars:
AIRFLOW_CTX_DAG_OWNER=atn
AIRFLOW_CTX_DAG_ID=atn_update_datalake
AIRFLOW_CTX_TASK_ID=check_datalake_quality_ctrl_step
AIRFLOW_CTX_EXECUTION_DATE=2023-01-06T13:21:32.663212+00:00
AIRFLOW_CTX_TRY_NUMBER=1
AIRFLOW_CTX_DAG_RUN_ID=manual__2023-01-06T13:21:32.663212+00:00
[2023-01-06T14:38:17.968+0000] {base.py:68} INFO - Using connection ID 'aws_credentials' for task execution.
[2023-01-06T14:38:17.968+0000] {connection_wrapper.py:210} INFO - AWS Connection (conn_id='aws_credentials', conn_type='aws') credentials retrieved from login and password.
[2023-01-06T14:38:18.006+0000] {emr.py:443} INFO - Poking step s-3650RIB09QRV0 on cluster j-3G7PO8Y3OE3BT
[2023-01-06T14:38:19.056+0000] {emr.py:69} INFO - Job flow currently PENDING
[2023-01-06T14:39:19.112+0000] {emr.py:443} INFO - Poking step s-3650RIB09QRV0 on cluster j-3G7PO8Y3OE3BT
[2023-01-06T14:39:20.181+0000] {emr.py:69} INFO - Job flow currently RUNNING
[2023-01-06T14:40:20.227+0000] {emr.py:443} INFO - Poking step s-3650RIB09QRV0 on cluster j-3G7PO8Y3OE3BT
[2023-01-06T14:40:21.446+0000] {emr.py:69} INFO - Job flow currently RUNNING
[2023-01-06T14:41:21.462+0000] {emr.py:443} INFO - Poking step s-3650RIB09QRV0 on cluster j-3G7PO8Y3OE3BT
[2023-01-06T14:41:22.688+0000] {emr.py:69} INFO - Job flow currently FAILED
[2023-01-06T14:41:22.715+0000] {taskinstance.py:1902} ERROR - Task failed with exception
Traceback (most recent call last):
  File "/home/airflow/.local/lib/python3.7/site-packages/airflow/sensors/base.py", line 277, in execute
    poke_return = self.poke(context)
  File "/home/airflow/.local/lib/python3.7/site-packages/airflow/providers/amazon/aws/sensors/emr.py", line 79, in poke
    raise AirflowException(final_message)
airflow.exceptions.AirflowException: EMR job failed for reason Unknown Error. with message None and log file s3://atn-dl-data/logs/j-3G7PO8Y3OE3BT/steps/s-3650RIB09QRV0/
[2023-01-06T14:41:22.723+0000] {taskinstance.py:1412} INFO - Marking task as UP_FOR_RETRY. dag_id=atn_update_datalake, task_id=check_datalake_quality_ctrl_step, execution_date=20230106T132132, start_date=20230106T143817, end_date=20230106T144122
[2023-01-06T14:41:22.742+0000] {standard_task_runner.py:97} ERROR - Failed to execute job 3953 for task check_datalake_quality_ctrl_step (EMR job failed for reason Unknown Error. with message None and log file s3://atn-dl-data/logs/j-3G7PO8Y3OE3BT/steps/s-3650RIB09QRV0/; 447)
[2023-01-06T14:41:22.775+0000] {local_task_job.py:156} INFO - Task exited with return code 1
[2023-01-06T14:41:22.823+0000] {local_task_job.py:279} INFO - 0 downstream tasks scheduled from follow-on schedule check
