[2023-01-08T16:24:39.530+0000] {taskinstance.py:1171} INFO - Dependencies all met for <TaskInstance: atn_update_datalake.check_datalake_quality_ctrl_step manual__2023-01-08T15:06:09.206673+00:00 [queued]>
[2023-01-08T16:24:39.546+0000] {taskinstance.py:1171} INFO - Dependencies all met for <TaskInstance: atn_update_datalake.check_datalake_quality_ctrl_step manual__2023-01-08T15:06:09.206673+00:00 [queued]>
[2023-01-08T16:24:39.546+0000] {taskinstance.py:1368} INFO - 
--------------------------------------------------------------------------------
[2023-01-08T16:24:39.546+0000] {taskinstance.py:1369} INFO - Starting attempt 2 of 3
[2023-01-08T16:24:39.546+0000] {taskinstance.py:1370} INFO - 
--------------------------------------------------------------------------------
[2023-01-08T16:24:39.560+0000] {taskinstance.py:1389} INFO - Executing <Task(EmrStepSensor): check_datalake_quality_ctrl_step> on 2023-01-08 15:06:09.206673+00:00
[2023-01-08T16:24:39.566+0000] {standard_task_runner.py:52} INFO - Started process 403 to run task
[2023-01-08T16:24:39.569+0000] {standard_task_runner.py:79} INFO - Running: ['***', 'tasks', 'run', 'atn_update_datalake', 'check_datalake_quality_ctrl_step', 'manual__2023-01-08T15:06:09.206673+00:00', '--job-id', '4090', '--raw', '--subdir', 'DAGS_FOLDER/market_data_analytics/my_dags/datalake_update.py', '--cfg-path', '/tmp/tmpz6_wx6jt', '--error-file', '/tmp/tmp2jx318fs']
[2023-01-08T16:24:39.570+0000] {standard_task_runner.py:80} INFO - Job 4090: Subtask check_datalake_quality_ctrl_step
[2023-01-08T16:24:39.720+0000] {task_command.py:371} INFO - Running <TaskInstance: atn_update_datalake.check_datalake_quality_ctrl_step manual__2023-01-08T15:06:09.206673+00:00 [running]> on host 370ed6868bc3
[2023-01-08T16:24:39.935+0000] {taskinstance.py:1583} INFO - Exporting the following env vars:
AIRFLOW_CTX_DAG_OWNER=atn
AIRFLOW_CTX_DAG_ID=atn_update_datalake
AIRFLOW_CTX_TASK_ID=check_datalake_quality_ctrl_step
AIRFLOW_CTX_EXECUTION_DATE=2023-01-08T15:06:09.206673+00:00
AIRFLOW_CTX_TRY_NUMBER=2
AIRFLOW_CTX_DAG_RUN_ID=manual__2023-01-08T15:06:09.206673+00:00
[2023-01-08T16:24:39.953+0000] {base.py:68} INFO - Using connection ID 'aws_credentials' for task execution.
[2023-01-08T16:24:39.954+0000] {connection_wrapper.py:210} INFO - AWS Connection (conn_id='aws_credentials', conn_type='aws') credentials retrieved from login and password.
[2023-01-08T16:24:40.028+0000] {emr.py:443} INFO - Poking step s-2HKIFMK1T35WA on cluster j-36MHGJC6JXK5R
[2023-01-08T16:24:40.927+0000] {emr.py:69} INFO - Job flow currently FAILED
[2023-01-08T16:24:40.943+0000] {taskinstance.py:1902} ERROR - Task failed with exception
Traceback (most recent call last):
  File "/home/airflow/.local/lib/python3.7/site-packages/airflow/sensors/base.py", line 277, in execute
    poke_return = self.poke(context)
  File "/home/airflow/.local/lib/python3.7/site-packages/airflow/providers/amazon/aws/sensors/emr.py", line 79, in poke
    raise AirflowException(final_message)
airflow.exceptions.AirflowException: EMR job failed for reason Unknown Error. with message None and log file s3://atn-dl-data/logs/j-36MHGJC6JXK5R/steps/s-2HKIFMK1T35WA/
[2023-01-08T16:24:40.947+0000] {taskinstance.py:1412} INFO - Marking task as UP_FOR_RETRY. dag_id=atn_update_datalake, task_id=check_datalake_quality_ctrl_step, execution_date=20230108T150609, start_date=20230108T162439, end_date=20230108T162440
[2023-01-08T16:24:40.967+0000] {standard_task_runner.py:97} ERROR - Failed to execute job 4090 for task check_datalake_quality_ctrl_step (EMR job failed for reason Unknown Error. with message None and log file s3://atn-dl-data/logs/j-36MHGJC6JXK5R/steps/s-2HKIFMK1T35WA/; 403)
[2023-01-08T16:24:41.029+0000] {local_task_job.py:156} INFO - Task exited with return code 1
[2023-01-08T16:24:41.100+0000] {local_task_job.py:279} INFO - 0 downstream tasks scheduled from follow-on schedule check
