[2023-01-08T16:25:42.839+0000] {taskinstance.py:1171} INFO - Dependencies all met for <TaskInstance: atn_update_datalake.check_datalake_quality_ctrl_step manual__2023-01-08T15:06:09.206673+00:00 [queued]>
[2023-01-08T16:25:42.897+0000] {taskinstance.py:1171} INFO - Dependencies all met for <TaskInstance: atn_update_datalake.check_datalake_quality_ctrl_step manual__2023-01-08T15:06:09.206673+00:00 [queued]>
[2023-01-08T16:25:42.897+0000] {taskinstance.py:1368} INFO - 
--------------------------------------------------------------------------------
[2023-01-08T16:25:42.897+0000] {taskinstance.py:1369} INFO - Starting attempt 3 of 3
[2023-01-08T16:25:42.898+0000] {taskinstance.py:1370} INFO - 
--------------------------------------------------------------------------------
[2023-01-08T16:25:42.955+0000] {taskinstance.py:1389} INFO - Executing <Task(EmrStepSensor): check_datalake_quality_ctrl_step> on 2023-01-08 15:06:09.206673+00:00
[2023-01-08T16:25:42.970+0000] {standard_task_runner.py:52} INFO - Started process 405 to run task
[2023-01-08T16:25:42.976+0000] {standard_task_runner.py:79} INFO - Running: ['***', 'tasks', 'run', 'atn_update_datalake', 'check_datalake_quality_ctrl_step', 'manual__2023-01-08T15:06:09.206673+00:00', '--job-id', '4091', '--raw', '--subdir', 'DAGS_FOLDER/market_data_analytics/my_dags/datalake_update.py', '--cfg-path', '/tmp/tmpdhsq0c2h', '--error-file', '/tmp/tmpwcxslwrt']
[2023-01-08T16:25:42.977+0000] {standard_task_runner.py:80} INFO - Job 4091: Subtask check_datalake_quality_ctrl_step
[2023-01-08T16:25:43.102+0000] {task_command.py:371} INFO - Running <TaskInstance: atn_update_datalake.check_datalake_quality_ctrl_step manual__2023-01-08T15:06:09.206673+00:00 [running]> on host 370ed6868bc3
[2023-01-08T16:25:43.370+0000] {taskinstance.py:1583} INFO - Exporting the following env vars:
AIRFLOW_CTX_DAG_OWNER=atn
AIRFLOW_CTX_DAG_ID=atn_update_datalake
AIRFLOW_CTX_TASK_ID=check_datalake_quality_ctrl_step
AIRFLOW_CTX_EXECUTION_DATE=2023-01-08T15:06:09.206673+00:00
AIRFLOW_CTX_TRY_NUMBER=3
AIRFLOW_CTX_DAG_RUN_ID=manual__2023-01-08T15:06:09.206673+00:00
[2023-01-08T16:25:43.388+0000] {base.py:68} INFO - Using connection ID 'aws_credentials' for task execution.
[2023-01-08T16:25:43.390+0000] {connection_wrapper.py:210} INFO - AWS Connection (conn_id='aws_credentials', conn_type='aws') credentials retrieved from login and password.
[2023-01-08T16:25:43.436+0000] {emr.py:443} INFO - Poking step s-2HKIFMK1T35WA on cluster j-36MHGJC6JXK5R
[2023-01-08T16:25:44.221+0000] {emr.py:69} INFO - Job flow currently FAILED
[2023-01-08T16:25:44.243+0000] {taskinstance.py:1902} ERROR - Task failed with exception
Traceback (most recent call last):
  File "/home/airflow/.local/lib/python3.7/site-packages/airflow/sensors/base.py", line 277, in execute
    poke_return = self.poke(context)
  File "/home/airflow/.local/lib/python3.7/site-packages/airflow/providers/amazon/aws/sensors/emr.py", line 79, in poke
    raise AirflowException(final_message)
airflow.exceptions.AirflowException: EMR job failed for reason Unknown Error. with message None and log file s3://atn-dl-data/logs/j-36MHGJC6JXK5R/steps/s-2HKIFMK1T35WA/
[2023-01-08T16:25:44.248+0000] {taskinstance.py:1412} INFO - Marking task as FAILED. dag_id=atn_update_datalake, task_id=check_datalake_quality_ctrl_step, execution_date=20230108T150609, start_date=20230108T162542, end_date=20230108T162544
[2023-01-08T16:25:44.261+0000] {standard_task_runner.py:97} ERROR - Failed to execute job 4091 for task check_datalake_quality_ctrl_step (EMR job failed for reason Unknown Error. with message None and log file s3://atn-dl-data/logs/j-36MHGJC6JXK5R/steps/s-2HKIFMK1T35WA/; 405)
[2023-01-08T16:25:44.276+0000] {local_task_job.py:156} INFO - Task exited with return code 1
[2023-01-08T16:25:44.331+0000] {local_task_job.py:279} INFO - 1 downstream tasks scheduled from follow-on schedule check
