[2023-01-05T10:51:52.738+0000] {taskinstance.py:1171} INFO - Dependencies all met for <TaskInstance: atn_import_data_from_apis.check_api_data_quality_ctrl_step manual__2023-01-05T10:05:00.167541+00:00 [queued]>
[2023-01-05T10:51:52.756+0000] {taskinstance.py:1171} INFO - Dependencies all met for <TaskInstance: atn_import_data_from_apis.check_api_data_quality_ctrl_step manual__2023-01-05T10:05:00.167541+00:00 [queued]>
[2023-01-05T10:51:52.756+0000] {taskinstance.py:1368} INFO - 
--------------------------------------------------------------------------------
[2023-01-05T10:51:52.756+0000] {taskinstance.py:1369} INFO - Starting attempt 1 of 3
[2023-01-05T10:51:52.756+0000] {taskinstance.py:1370} INFO - 
--------------------------------------------------------------------------------
[2023-01-05T10:51:52.772+0000] {taskinstance.py:1389} INFO - Executing <Task(EmrStepSensor): check_api_data_quality_ctrl_step> on 2023-01-05 10:05:00.167541+00:00
[2023-01-05T10:51:52.777+0000] {standard_task_runner.py:52} INFO - Started process 235 to run task
[2023-01-05T10:51:52.781+0000] {standard_task_runner.py:79} INFO - Running: ['***', 'tasks', 'run', 'atn_import_data_from_apis', 'check_api_data_quality_ctrl_step', 'manual__2023-01-05T10:05:00.167541+00:00', '--job-id', '3741', '--raw', '--subdir', 'DAGS_FOLDER/market_data_analytics/my_dags/import_data_from_apis.py', '--cfg-path', '/tmp/tmpg6g48rrg', '--error-file', '/tmp/tmphoyrovg3']
[2023-01-05T10:51:52.782+0000] {standard_task_runner.py:80} INFO - Job 3741: Subtask check_api_data_quality_ctrl_step
[2023-01-05T10:51:52.858+0000] {task_command.py:371} INFO - Running <TaskInstance: atn_import_data_from_apis.check_api_data_quality_ctrl_step manual__2023-01-05T10:05:00.167541+00:00 [running]> on host 370ed6868bc3
[2023-01-05T10:51:52.978+0000] {taskinstance.py:1583} INFO - Exporting the following env vars:
AIRFLOW_CTX_DAG_OWNER=atn
AIRFLOW_CTX_DAG_ID=atn_import_data_from_apis
AIRFLOW_CTX_TASK_ID=check_api_data_quality_ctrl_step
AIRFLOW_CTX_EXECUTION_DATE=2023-01-05T10:05:00.167541+00:00
AIRFLOW_CTX_TRY_NUMBER=1
AIRFLOW_CTX_DAG_RUN_ID=manual__2023-01-05T10:05:00.167541+00:00
[2023-01-05T10:51:52.989+0000] {base.py:68} INFO - Using connection ID 'aws_credentials' for task execution.
[2023-01-05T10:51:52.990+0000] {connection_wrapper.py:210} INFO - AWS Connection (conn_id='aws_credentials', conn_type='aws') credentials retrieved from login and password.
[2023-01-05T10:51:53.034+0000] {emr.py:443} INFO - Poking step s-38VPHEXMVCDD on cluster j-275LF5U6JZLEP
[2023-01-05T10:51:53.838+0000] {emr.py:69} INFO - Job flow currently PENDING
[2023-01-05T10:52:53.854+0000] {emr.py:443} INFO - Poking step s-38VPHEXMVCDD on cluster j-275LF5U6JZLEP
[2023-01-05T10:52:54.727+0000] {emr.py:69} INFO - Job flow currently RUNNING
[2023-01-05T10:53:54.787+0000] {emr.py:443} INFO - Poking step s-38VPHEXMVCDD on cluster j-275LF5U6JZLEP
[2023-01-05T10:53:55.762+0000] {emr.py:69} INFO - Job flow currently FAILED
[2023-01-05T10:53:55.784+0000] {taskinstance.py:1902} ERROR - Task failed with exception
Traceback (most recent call last):
  File "/home/airflow/.local/lib/python3.7/site-packages/airflow/sensors/base.py", line 277, in execute
    poke_return = self.poke(context)
  File "/home/airflow/.local/lib/python3.7/site-packages/airflow/providers/amazon/aws/sensors/emr.py", line 79, in poke
    raise AirflowException(final_message)
airflow.exceptions.AirflowException: EMR job failed for reason Unknown Error. with message None and log file s3://atn-dl-data/logs/j-275LF5U6JZLEP/steps/s-38VPHEXMVCDD/
[2023-01-05T10:53:55.800+0000] {taskinstance.py:1412} INFO - Marking task as UP_FOR_RETRY. dag_id=atn_import_data_from_apis, task_id=check_api_data_quality_ctrl_step, execution_date=20230105T100500, start_date=20230105T105152, end_date=20230105T105355
[2023-01-05T10:53:55.829+0000] {standard_task_runner.py:97} ERROR - Failed to execute job 3741 for task check_api_data_quality_ctrl_step (EMR job failed for reason Unknown Error. with message None and log file s3://atn-dl-data/logs/j-275LF5U6JZLEP/steps/s-38VPHEXMVCDD/; 235)
[2023-01-05T10:53:55.866+0000] {local_task_job.py:156} INFO - Task exited with return code 1
[2023-01-05T10:53:55.919+0000] {local_task_job.py:279} INFO - 0 downstream tasks scheduled from follow-on schedule check
